from django.contrib.auth import get_user_model
from posts.models import Comment, Follow, Group, Post
from rest_framework import serializers
from rest_framework.relations import SlugRelatedField
from rest_framework.validators import UniqueTogetherValidator

User = get_user_model()


class PostSerializer(serializers.ModelSerializer):
    author = SlugRelatedField(slug_field='username', read_only=True)

    class Meta:
        fields = '__all__'
        model = Post
        read_only_fields = ('pub_date',)


class CommentSerializer(serializers.ModelSerializer):
    author = serializers.SlugRelatedField(
        read_only=True, slug_field='username'
    )

    class Meta:
        fields = '__all__'
        model = Comment
        read_only_fields = ('author', 'post', 'created',)


class GroupSerializer(serializers.ModelSerializer):

    class Meta:
        fields = ('id', 'title', 'slug', 'description')
        model = Group


class FollowSerializer(serializers.ModelSerializer):
    user = serializers.SlugRelatedField(
        queryset=User.objects.all(),
        slug_field='username',
        default=serializers.CurrentUserDefault()
    )
    following = serializers.SlugRelatedField(
        queryset=User.objects.all(),
        slug_field='username'
    )

    class Meta:
        fields = ('user', 'following')
        model = Follow
        validators = [
            UniqueTogetherValidator(
                queryset=Follow.objects.all(),
                fields=('user', 'following'),
                message='Подписка уже существует'
            )
        ]

    def validate_following(self, value):
        if (self.context['request'].user == value
                and self.context['request'].method == 'POST'):
            raise serializers.ValidationError(
                'Нельзя подписаться на самого себя!'
            )
        return value
